{
 "cells": [
  {
   "cell_type": "code",
   "execution_count": 2,
   "id": "6aa3809d",
   "metadata": {},
   "outputs": [
    {
     "name": "stdout",
     "output_type": "stream",
     "text": [
      "Collecting tflite-model-maker-nightlyNote: you may need to restart the kernel to use updated packages.\n",
      "\n",
      "  Using cached tflite_model_maker_nightly-0.4.3.dev202307110517-py3-none-any.whl (580 kB)\n",
      "Collecting Cython>=0.29.13\n",
      "  Downloading Cython-3.0.0-cp310-cp310-win_amd64.whl (2.8 MB)\n",
      "     ---------------------------------------- 2.8/2.8 MB 4.5 MB/s eta 0:00:00\n",
      "Collecting matplotlib<3.5.0,>=3.0.3\n",
      "  Downloading matplotlib-3.4.3.tar.gz (37.9 MB)\n",
      "     --------------                           14.0/37.9 MB 3.0 MB/s eta 0:00:08\n"
     ]
    },
    {
     "name": "stderr",
     "output_type": "stream",
     "text": [
      "ERROR: Exception:\n",
      "Traceback (most recent call last):\n",
      "  File \"C:\\Users\\lenovo\\anaconda3\\lib\\site-packages\\pip\\_vendor\\urllib3\\response.py\", line 437, in _error_catcher\n",
      "    yield\n",
      "  File \"C:\\Users\\lenovo\\anaconda3\\lib\\site-packages\\pip\\_vendor\\urllib3\\response.py\", line 560, in read\n",
      "    data = self._fp_read(amt) if not fp_closed else b\"\"\n",
      "  File \"C:\\Users\\lenovo\\anaconda3\\lib\\site-packages\\pip\\_vendor\\urllib3\\response.py\", line 526, in _fp_read\n",
      "    return self._fp.read(amt) if amt is not None else self._fp.read()\n",
      "  File \"C:\\Users\\lenovo\\anaconda3\\lib\\site-packages\\pip\\_vendor\\cachecontrol\\filewrapper.py\", line 90, in read\n",
      "    data = self.__fp.read(amt)\n",
      "  File \"C:\\Users\\lenovo\\anaconda3\\lib\\http\\client.py\", line 465, in read\n",
      "    s = self.fp.read(amt)\n",
      "  File \"C:\\Users\\lenovo\\anaconda3\\lib\\socket.py\", line 705, in readinto\n",
      "    return self._sock.recv_into(b)\n",
      "  File \"C:\\Users\\lenovo\\anaconda3\\lib\\ssl.py\", line 1274, in recv_into\n",
      "    return self.read(nbytes, buffer)\n",
      "  File \"C:\\Users\\lenovo\\anaconda3\\lib\\ssl.py\", line 1130, in read\n",
      "    return self._sslobj.read(len, buffer)\n",
      "ssl.SSLError: [SSL: DECRYPTION_FAILED_OR_BAD_RECORD_MAC] decryption failed or bad record mac (_ssl.c:2548)\n",
      "\n",
      "During handling of the above exception, another exception occurred:\n",
      "\n",
      "Traceback (most recent call last):\n",
      "  File \"C:\\Users\\lenovo\\anaconda3\\lib\\site-packages\\pip\\_internal\\cli\\base_command.py\", line 160, in exc_logging_wrapper\n",
      "    status = run_func(*args)\n",
      "  File \"C:\\Users\\lenovo\\anaconda3\\lib\\site-packages\\pip\\_internal\\cli\\req_command.py\", line 247, in wrapper\n",
      "    return func(self, options, args)\n",
      "  File \"C:\\Users\\lenovo\\anaconda3\\lib\\site-packages\\pip\\_internal\\commands\\install.py\", line 400, in run\n",
      "    requirement_set = resolver.resolve(\n",
      "  File \"C:\\Users\\lenovo\\anaconda3\\lib\\site-packages\\pip\\_internal\\resolution\\resolvelib\\resolver.py\", line 92, in resolve\n",
      "    result = self._result = resolver.resolve(\n",
      "  File \"C:\\Users\\lenovo\\anaconda3\\lib\\site-packages\\pip\\_vendor\\resolvelib\\resolvers.py\", line 481, in resolve\n",
      "    state = resolution.resolve(requirements, max_rounds=max_rounds)\n",
      "  File \"C:\\Users\\lenovo\\anaconda3\\lib\\site-packages\\pip\\_vendor\\resolvelib\\resolvers.py\", line 373, in resolve\n",
      "    failure_causes = self._attempt_to_pin_criterion(name)\n",
      "  File \"C:\\Users\\lenovo\\anaconda3\\lib\\site-packages\\pip\\_vendor\\resolvelib\\resolvers.py\", line 213, in _attempt_to_pin_criterion\n",
      "    criteria = self._get_updated_criteria(candidate)\n",
      "  File \"C:\\Users\\lenovo\\anaconda3\\lib\\site-packages\\pip\\_vendor\\resolvelib\\resolvers.py\", line 204, in _get_updated_criteria\n",
      "    self._add_to_criteria(criteria, requirement, parent=candidate)\n",
      "  File \"C:\\Users\\lenovo\\anaconda3\\lib\\site-packages\\pip\\_vendor\\resolvelib\\resolvers.py\", line 172, in _add_to_criteria\n",
      "    if not criterion.candidates:\n",
      "  File \"C:\\Users\\lenovo\\anaconda3\\lib\\site-packages\\pip\\_vendor\\resolvelib\\structs.py\", line 151, in __bool__\n",
      "    return bool(self._sequence)\n",
      "  File \"C:\\Users\\lenovo\\anaconda3\\lib\\site-packages\\pip\\_internal\\resolution\\resolvelib\\found_candidates.py\", line 155, in __bool__\n",
      "    return any(self)\n",
      "  File \"C:\\Users\\lenovo\\anaconda3\\lib\\site-packages\\pip\\_internal\\resolution\\resolvelib\\found_candidates.py\", line 143, in <genexpr>\n",
      "    return (c for c in iterator if id(c) not in self._incompatible_ids)\n",
      "  File \"C:\\Users\\lenovo\\anaconda3\\lib\\site-packages\\pip\\_internal\\resolution\\resolvelib\\found_candidates.py\", line 47, in _iter_built\n",
      "    candidate = func()\n",
      "  File \"C:\\Users\\lenovo\\anaconda3\\lib\\site-packages\\pip\\_internal\\resolution\\resolvelib\\factory.py\", line 206, in _make_candidate_from_link\n",
      "    self._link_candidate_cache[link] = LinkCandidate(\n",
      "  File \"C:\\Users\\lenovo\\anaconda3\\lib\\site-packages\\pip\\_internal\\resolution\\resolvelib\\candidates.py\", line 297, in __init__\n",
      "    super().__init__(\n",
      "  File \"C:\\Users\\lenovo\\anaconda3\\lib\\site-packages\\pip\\_internal\\resolution\\resolvelib\\candidates.py\", line 162, in __init__\n",
      "    self.dist = self._prepare()\n",
      "  File \"C:\\Users\\lenovo\\anaconda3\\lib\\site-packages\\pip\\_internal\\resolution\\resolvelib\\candidates.py\", line 231, in _prepare\n",
      "    dist = self._prepare_distribution()\n",
      "  File \"C:\\Users\\lenovo\\anaconda3\\lib\\site-packages\\pip\\_internal\\resolution\\resolvelib\\candidates.py\", line 308, in _prepare_distribution\n",
      "    return preparer.prepare_linked_requirement(self._ireq, parallel_builds=True)\n",
      "  File \"C:\\Users\\lenovo\\anaconda3\\lib\\site-packages\\pip\\_internal\\operations\\prepare.py\", line 491, in prepare_linked_requirement\n",
      "    return self._prepare_linked_requirement(req, parallel_builds)\n",
      "  File \"C:\\Users\\lenovo\\anaconda3\\lib\\site-packages\\pip\\_internal\\operations\\prepare.py\", line 536, in _prepare_linked_requirement\n",
      "    local_file = unpack_url(\n",
      "  File \"C:\\Users\\lenovo\\anaconda3\\lib\\site-packages\\pip\\_internal\\operations\\prepare.py\", line 166, in unpack_url\n",
      "    file = get_http_url(\n",
      "  File \"C:\\Users\\lenovo\\anaconda3\\lib\\site-packages\\pip\\_internal\\operations\\prepare.py\", line 107, in get_http_url\n",
      "    from_path, content_type = download(link, temp_dir.path)\n",
      "  File \"C:\\Users\\lenovo\\anaconda3\\lib\\site-packages\\pip\\_internal\\network\\download.py\", line 147, in __call__\n",
      "    for chunk in chunks:\n",
      "  File \"C:\\Users\\lenovo\\anaconda3\\lib\\site-packages\\pip\\_internal\\cli\\progress_bars.py\", line 53, in _rich_progress_bar\n",
      "    for chunk in iterable:\n",
      "  File \"C:\\Users\\lenovo\\anaconda3\\lib\\site-packages\\pip\\_internal\\network\\utils.py\", line 63, in response_chunks\n",
      "    for chunk in response.raw.stream(\n",
      "  File \"C:\\Users\\lenovo\\anaconda3\\lib\\site-packages\\pip\\_vendor\\urllib3\\response.py\", line 621, in stream\n",
      "    data = self.read(amt=amt, decode_content=decode_content)\n",
      "  File \"C:\\Users\\lenovo\\anaconda3\\lib\\site-packages\\pip\\_vendor\\urllib3\\response.py\", line 559, in read\n",
      "    with self._error_catcher():\n",
      "  File \"C:\\Users\\lenovo\\anaconda3\\lib\\contextlib.py\", line 153, in __exit__\n",
      "    self.gen.throw(typ, value, traceback)\n",
      "  File \"C:\\Users\\lenovo\\anaconda3\\lib\\site-packages\\pip\\_vendor\\urllib3\\response.py\", line 448, in _error_catcher\n",
      "    raise SSLError(e)\n",
      "pip._vendor.urllib3.exceptions.SSLError: [SSL: DECRYPTION_FAILED_OR_BAD_RECORD_MAC] decryption failed or bad record mac (_ssl.c:2548)\n"
     ]
    }
   ],
   "source": [
    "pip install tflite-model-maker-nightly"
   ]
  },
  {
   "cell_type": "code",
   "execution_count": 4,
   "id": "9d375b25",
   "metadata": {},
   "outputs": [
    {
     "ename": "ModuleNotFoundError",
     "evalue": "No module named 'tflite_model_maker'",
     "output_type": "error",
     "traceback": [
      "\u001b[1;31m---------------------------------------------------------------------------\u001b[0m",
      "\u001b[1;31mModuleNotFoundError\u001b[0m                       Traceback (most recent call last)",
      "Cell \u001b[1;32mIn[4], line 1\u001b[0m\n\u001b[1;32m----> 1\u001b[0m \u001b[38;5;28;01mfrom\u001b[39;00m \u001b[38;5;21;01mtflite_model_maker\u001b[39;00m \u001b[38;5;28;01mimport\u001b[39;00m image_classifier\n\u001b[0;32m      2\u001b[0m \u001b[38;5;28;01mfrom\u001b[39;00m \u001b[38;5;21;01mtflite_model_maker\u001b[39;00m\u001b[38;5;21;01m.\u001b[39;00m\u001b[38;5;21;01mimage_classifier\u001b[39;00m \u001b[38;5;28;01mimport\u001b[39;00m DataLoader\n",
      "\u001b[1;31mModuleNotFoundError\u001b[0m: No module named 'tflite_model_maker'"
     ]
    }
   ],
   "source": [
    "from tflite_model_maker import image_classifier\n",
    "from tflite_model_maker.image_classifier import DataLoader"
   ]
  },
  {
   "cell_type": "code",
   "execution_count": 5,
   "id": "7bcfd3c0",
   "metadata": {},
   "outputs": [
    {
     "ename": "ModuleNotFoundError",
     "evalue": "No module named 'tflite_model_maker'",
     "output_type": "error",
     "traceback": [
      "\u001b[1;31m---------------------------------------------------------------------------\u001b[0m",
      "\u001b[1;31mModuleNotFoundError\u001b[0m                       Traceback (most recent call last)",
      "Cell \u001b[1;32mIn[5], line 1\u001b[0m\n\u001b[1;32m----> 1\u001b[0m \u001b[38;5;28;01mfrom\u001b[39;00m \u001b[38;5;21;01mtflite_model_maker\u001b[39;00m \u001b[38;5;28;01mimport\u001b[39;00m image_classifier\n\u001b[0;32m      2\u001b[0m \u001b[38;5;28;01mfrom\u001b[39;00m \u001b[38;5;21;01mtflite_model_maker\u001b[39;00m\u001b[38;5;21;01m.\u001b[39;00m\u001b[38;5;21;01mimage_classifier\u001b[39;00m \u001b[38;5;28;01mimport\u001b[39;00m DataLoader\n",
      "\u001b[1;31mModuleNotFoundError\u001b[0m: No module named 'tflite_model_maker'"
     ]
    }
   ],
   "source": [
    "from tflite_model_maker import image_classifier\n",
    "from tflite_model_maker.image_classifier import DataLoader"
   ]
  }
 ],
 "metadata": {
  "kernelspec": {
   "display_name": "Python 3 (ipykernel)",
   "language": "python",
   "name": "python3"
  },
  "language_info": {
   "codemirror_mode": {
    "name": "ipython",
    "version": 3
   },
   "file_extension": ".py",
   "mimetype": "text/x-python",
   "name": "python",
   "nbconvert_exporter": "python",
   "pygments_lexer": "ipython3",
   "version": "3.10.9"
  }
 },
 "nbformat": 4,
 "nbformat_minor": 5
}
